Workbook
Name DatosExternos_1: search_ISBI!$A$1:$B$686

Sheet search_ISBI
A1: Title | B1: Year | C1: DOI | D1: Screening 1 | E1: Review full | F1: Reason | G1: 1 | H1: 2 | I1: 3 | J1: 4 | K1: 5 | L1: 6 | M1: 7 | N1: 8 | O1: 9 | P1: 10 | Q1: 11 | R1: 12 | S1: 13 | T1: 14
A2: Legopet: Hierarchical Feature Guided Conditional Diffusion for Pet Image Reconstruction | B2: 2025 | C2: 10.1109/ISBI60581.2025.10980656 | D2: No
A3: On Frequency Domain Adversarial Vulnerabilities of Volumetric Medical Image Segmentation | B3: 2025 | C3: 10.1109/ISBI60581.2025.10981075 | D3: No
A4: Integrations: Informed Subset Selection Based Generation for Medical Imaging in Resource Constrained Setting | B4: 2025 | C4: 10.1109/ISBI60581.2025.10980935 | D4: No
A5: Targeting Prostate Biopsy: A Straightforward CNN Solution for 3D MR-Trus Image Registration | B5: 2025 | C5: 10.1109/ISBI60581.2025.10981223 | D5: No
A6: Conditional Convolution of Clinical Data Embeddings for Multimodal Prostate Cancer Classification | B6: 2025 | C6: 10.1109/ISBI60581.2025.10981307 | D6: Yes | E6: Yes | G6: Yes | H6: Partially | I6: Yes | J6: No | K6: Yes | L6: Partially | M6: Yes | N6: No | O6: Partially | P6: Partially | Q6: Partially | R6: Partially | S6: No | T6: Yes
A7: Predicting Response to Neoadjuvant Chemotherapy using Multi-Modal MRI Radiomics and Machine Learning Approaches | B7: 2025 | C7: 10.1109/ISBI60581.2025.10980916 | D7: Yes | E7: Yes | G7: Yes | H7: Partially | I7: Yes | J7: No | K7: Yes | L7: Partially | M7: Yes | N7: No | O7: Partially | P7: Partially | Q7: Partially | R7: Partially | S7: No | T7: No
A8: Towards Classifying Histopathological Microscope Images as Time Series Data | B8: 2025 | C8: 10.1109/ISBI60581.2025.10981309 | D8: Yes | E8: Yes | G8: Yes | H8: Partially | I8: Yes | J8: No | K8: Yes | L8: Partially | M8: Yes | N8: No | O8: Partially | P8: Partially | Q8: Partially | R8: Partially | S8: No | T8: No
A9: Machine Learning-Based Polysomnography Data Analysis for ADHD Diagnosis: A Focus on Sleep Stage-Based Biomarkers | B9: 2025 | C9: 10.1109/ISBI60581.2025.10981031 | D9: Yes | E9: Yes | G9: Yes | H9: Yes | I9: Yes | J9: No | K9: Yes | L9: Partially | M9: Yes | N9: No | O9: Partially | P9: Partially | Q9: Partially | R9: Partially | S9: No | T9: Yes
A10: Attention-Based Multiple Instance Learning for Achilles Tendinopathy Detection in Ultrasound Imaging | B10: 2025 | C10: 10.1109/ISBI60581.2025.10981252 | D10: Yes | E10: Yes | G10: Yes | H10: Partially | I10: Yes | J10: No | K10: Yes | L10: Yes | M10: Yes | N10: No | O10: Partially | P10: Partially | Q10: Partially | R10: Partially | S10: Partially | T10: No
A11: Ensemble of Foundation Models for Pap Smear Cell Analysis | B11: 2025 | C11: 10.1109/ISBI60581.2025.10981009 | D11: Yes | E11: Yes | G11: Yes | H11: No | I11: Yes | J11: No | K11: Yes | L11: Partially | M11: Yes | N11: No | O11: No | P11: No | Q11: Partially | R11: Partially | S11: Partially | T11: Yes
A12: Polyp Detection in Colonoscopy Videos via Boosted Multi-Scale Feature Fusion | B12: 2025 | C12: 10.1109/ISBI60581.2025.10981030 | D12: Yes | E12: Yes | G12: Yes | H12: Partially | I12: Yes | J12: No | K12: Yes | L12: Partially | M12: Yes | N12: No | O12: Partially | P12: No | Q12: Partially | R12: No | S12: No | T12: No
A13: Multimodal Learning for Enhanced Detection in Oral Cancer Screening | B13: 2025 | C13: 10.1109/ISBI60581.2025.10981235 | D13: Yes | E13: Yes | G13: Yes | H13: No | I13: No | J13: No | K13: Yes | L13: Partially | M13: Yes | N13: No | O13: No | P13: No | Q13: Partially | R13: Partially | S13: No | T13: No
A14: Accelerating Water Removal in MRSI Using Domain Knowledge-Based Deep Learning | B14: 2025 | C14: 10.1109/ISBI60581.2025.10980704 | D14: No
A15: BAY-MED: Bayesian Approximation for Post-Hoc Uncertainty in Medical Imaging | B15: 2025 | C15: 10.1109/ISBI60581.2025.10981251 | D15: No
A16: Conditional Generative Models for Contrast-Enhanced Synthesis of T1W and T1 Maps in Brain MRI | B16: 2025 | C16: 10.1109/ISBI60581.2025.10980893 | D16: No
A17: Gland Segmentation Using SAM with Cancer Grade As A Prompt | B17: 2025 | C17: 10.1109/ISBI60581.2025.10980744 | D17: No
A18: Instance-Aware Deep Learning for Liver Metastasis Segmentation | B18: 2025 | C18: 10.1109/ISBI60581.2025.10980698 | D18: No
A19: Video-Based Surgical Tool-Tip and Keypoint Tracking Using Multi-Frame Context-Driven Deep Learning Models | B19: 2025 | C19: 10.1109/ISBI60581.2025.10980959 | D19: No
A20: RadHop-Net: A Lightweight Radiomics-to-Error Regression for False Positive Reduction in MRI Prostate Cancer Detection | B20: 2025 | C20: 10.1109/ISBI60581.2025.10980816 | D20: Yes | E20: Yes | G20: Yes | H20: Partially | I20: Yes | J20: No | K20: Yes | L20: Yes | M20: Yes | N20: No | O20: Partially | P20: Partially | Q20: Partially | R20: Partially | S20: Partially | T20: No
A21: Segmentation of Hemorrhagic Stroke Using Graph Convolutional Network | B21: 2025 | C21: 10.1109/ISBI60581.2025.10980721 | D21: No
A22: Fully Unsupervised Deep Spectral Clustering for Retinal Vessel Segmentation | B22: 2025 | C22: 10.1109/ISBI60581.2025.10981224 | D22: No
A23: Diffusion-Based Multi-Degradation Remover for Fiber Bundle Image Restoration | B23: 2025 | C23: 10.1109/ISBI60581.2025.10980949 | D23: No
A24: BOrg: A Brain Organoid-Based Mitosis Dataset for Automatic Analysis of Brain Diseases | B24: 2025 | C24: 10.1109/ISBI60581.2025.10980679 | D24: No
A25: Deep Modeling and Optimization of Medical Image Classification | B25: 2025 | C25: 10.1109/ISBI60581.2025.10981184 | D25: Yes | E25: Yes | G25: Partially | H25: No | I25: No | J25: No | K25: Yes | L25: No | M25: Yes | N25: Yes | O25: Partially | P25: No | Q25: Partially | R25: Partially | S25: No | T25: Yes
A26: Prompting Medical Vision-Language Models to Mitigate Diagnosis Bias by Generating Realistic Dermoscopic Images | B26: 2025 | C26: 10.1109/ISBI60581.2025.10980892 | D26: No
A27: Classification of Oral Potentially Malignant Disorders Using Multimodal Feature Integration | B27: 2025 | C27: 10.1109/ISBI60581.2025.10980715 | D27: Yes | E27: Yes | G27: Yes | H27: Partially | I27: Yes | J27: No | K27: Yes | L27: Partially | M27: Yes | N27: Yes | O27: Partially | P27: No | Q27: Partially | R27: Partially | S27: Partially | T27: Yes
A28: C-ARM Guidance: A Self-Supervised Approach to Automated Positioning During Stroke Thrombectomy | B28: 2025 | C28: 10.1109/ISBI60581.2025.10980945 | D28: No
A29: Parameter Choices in Haarpsi for IQA with Medical Images | B29: 2025 | C29: 10.1109/ISBI60581.2025.10981227 | D29: No
A30: Measuring Impact of Super-Resolution on Spinal Cord MRI Scans: Lesion Detection Sensitivity, Variability, and Clinical Impact | B30: 2025 | C30: 10.1109/ISBI60581.2025.10981088 | D30: No
A31: Machine Learning Fairness for Depression Detection Using EEG Data | B31: 2025 | C31: 10.1109/ISBI60581.2025.10980986 | D31: No
A32: Spreading Depolarization Detection in Electrocorticogram Spectrogram Imaging by Deep Learning: Is it Just About Delta Band? | B32: 2025 | C32: 10.1109/ISBI60581.2025.10980689 | D32: Yes | E32: Yes | G32: Yes | H32: Partially | I32: Yes | J32: No | K32: Yes | L32: Partially | M32: Yes | N32: No | O32: Partially | P32: Partially | Q32: Partially | R32: Partially | S32: No | T32: No
A33: Attention-Driven Multi-Sequence Mri Feature Learning and Fusion for Breast Cancer Diagnosis | B33: 2025 | C33: 10.1109/ISBI60581.2025.10981203 | D33: Yes | E33: Yes | G33: Yes | H33: Partially | I33: Yes | J33: No | K33: Yes | L33: Partially | M33: Yes | N33: No | O33: Partially | P33: Partially | Q33: Partially | R33: Partially | S33: No | T33: No
A34: Beyond Occlusion: In Search for Near Real-Time Explainability of CNN-Based Prostate Cancer Classification | B34: 2025 | C34: 10.1109/ISBI60581.2025.10980802 | D34: No
A35: EMViR - Electron Microscopy Image Dataset Of Labelled Respiratory Viruses For Deep Learning Model Development | B35: 2025 | C35: 10.1109/ISBI60581.2025.10980686 | D35: No
A36: Generating Customized Prompts for Zero-Shot Rare Event Medical Image Classification Using LLM | B36: 2025 | C36: 10.1109/ISBI60581.2025.10981040 | D36: No
A37: Adaptive Whole-Body Pet Image Denoising Using 3D Diffusion Models with Controlnet | B37: 2025 | C37: 10.1109/ISBI60581.2025.10980878 | D37: No
A38: Easy and Hard Partitions: An Investigation On Dataset Partitions in Biomedical Image Analysis | B38: 2025 | C38: 10.1109/ISBI60581.2025.10981289 | D38: No
A39: Enhancing Dementia Detection: Augmenting the Face Mesh | B39: 2025 | C39: 10.1109/ISBI60581.2025.10980957 | D39: Yes | E39: Yes | G39: Yes | H39: Partially | I39: Yes | J39: No | K39: Yes | L39: No | M39: Yes | N39: No | O39: Partially | P39: No | Q39: Partially | R39: Partially | S39: No | T39: No
A40: Medical Image Quality Assessment Based on Probability of Necessity and Sufficiency | B40: 2025 | C40: 10.1109/ISBI60581.2025.10981239 | D40: No
...

Sheet Hoja1
C70: Data sources (CLAIM 7) | D70: Inclusion and exclusion criteria (CLAIM 8) | E70: Selection of data subsets (CLAIM 10) | F70: How missing data were handled (CLAIM 12) | G70: Metrics of model performance (CLAIM 28) | H70: Statistical measures of significance and uncertainty (CLAIM 29) | I70: Evaluation on internal data (CLAIM 32) | J70: Testing on external data (CLAIM 33) | K70: Numbers of patients or examinations included and excluded (CLAIM 35) | L70: Demographic and clinical characteristics of cases in each partition (CLAIM36) | M70: Performance metrics and measures of statistical uncertainty (CLAIM 37) | N70: Estimates of diagnostic performance and their precision (CLIAM 38) | O70: Failure analysis of incorrect results (CLAIM 39) | P70: Public availability (code)
B71: Yes | C71: =(COUNTIF(search_ISBI!G2:G686,"Yes")/COUNTA(search_ISBI!G2:G686)) -> 0.92592593 | D71: 10 | E71: =(COUNTIF(search_ISBI!I2:I686,"Yes")/COUNTA(search_ISBI!I2:I686)) -> 0.86419753 | F71: =(COUNTIF(search_ISBI!J2:J686,"Yes")/COUNTA(search_ISBI!J2:J686)) -> 0.082304527 | G71: =(COUNTIF(search_ISBI!K2:K686,"Yes")/COUNTA(search_ISBI!K2:K686)) -> 0.87654321 | H71: =(COUNTIF(search_ISBI!L2:L686,"Yes")/COUNTA(search_ISBI!L2:L686)) -> 0.19341564 | I71: =(COUNTIF(search_ISBI!M2:M686,"Yes")/COUNTA(search_ISBI!M2:M686)) -> 0.97942387 | J71: =(COUNTIF(search_ISBI!N2:N686,"Yes")/COUNTA(search_ISBI!N2:N686)) -> 0.16049383 | K71: =(COUNTIF(search_ISBI!O2:O686,"Yes")/COUNTA(search_ISBI!O2:O686)) -> 0.061728395 | L71: =(COUNTIF(search_ISBI!P2:P686,"Yes")/COUNTA(search_ISBI!P2:P686)) -> 0.049382716 | ... P71: =(COUNTIF(search_ISBI!T2:T686,"Yes")/COUNTA(search_ISBI!T2:T686)) -> 0.18930041
B72: No | C72: =COUNTIF(search_ISBI!G2:G686,"No")/COUNTA(search_ISBI!G2:G686) -> 0 | D72: =COUNTIF(search_ISBI!H2:H686,"No")/COUNTA(search_ISBI!H2:H686) -> 0.10699588 | E72: =COUNTIF(search_ISBI!I2:I686,"No")/COUNTA(search_ISBI!I2:I686) -> 0.037037037 | F72: =COUNTIF(search_ISBI!J2:J686,"No")/COUNTA(search_ISBI!J2:J686) -> 0.83127572 | G72: =COUNTIF(search_ISBI!K2:K686,"No")/COUNTA(search_ISBI!K2:K686) -> 0.0041152263 | H72: =COUNTIF(search_ISBI!L2:L686,"No")/COUNTA(search_ISBI!L2:L686) -> 0.37037037 | I72: =COUNTIF(search_ISBI!M2:M686,"No")/COUNTA(search_ISBI!M2:M686) -> 0.020576132 | J72: =COUNTIF(search_ISBI!N2:N686,"No")/COUNTA(search_ISBI!N2:N686) -> 0.82304527 | ... P72: =COUNTIF(search_ISBI!T2:T686,"No")/COUNTA(search_ISBI!T2:T686) -> 0.81069959
B73: Partially | C73: =COUNTIF(search_ISBI!G2:G686,"Partially")/COUNTA(search_ISBI!G2:G686) -> 0.074074074 | D73: =COUNTIF(search_ISBI!H2:H686,"Partially")/COUNTA(search_ISBI!H2:H686) -> 0.81069959 | E73: =COUNTIF(search_ISBI!I2:I686,"Partially")/COUNTA(search_ISBI!I2:I686) -> 0.094650206 | F73: =COUNTIF(search_ISBI!J2:J686,"Partially")/COUNTA(search_ISBI!J2:J686) -> 0.049382716 | G73: =COUNTIF(search_ISBI!K2:K686,"Partially")/COUNTA(search_ISBI!K2:K686) -> 0.11934156 | H73: =COUNTIF(search_ISBI!L2:L686,"Partially")/COUNTA(search_ISBI!L2:L686) -> 0.43621399 | I73: =COUNTIF(search_ISBI!M2:M686,"Partially")/COUNTA(search_ISBI!M2:M686) -> 0 | J73: =COUNTIF(search_ISBI!N2:N686,"Partially")/COUNTA(search_ISBI!N2:N686) -> 0.016460905 | ... P73: =COUNTIF(search_ISBI!T2:T686,"Partially")/COUNTA(search_ISBI!T2:T686) -> 0
B74: N.A | C74: =COUNTIF(search_ISBI!G2:G686,"N.A")/COUNTA(search_ISBI!G2:G686) -> 0 | D74: =COUNTIF(search_ISBI!H2:H686,"N.A")/COUNTA(search_ISBI!H2:H686) -> 0 | E74: =COUNTIF(search_ISBI!I2:I686,"N.A")/COUNTA(search_ISBI!I2:I686) -> 0.0041152263 | F74: =COUNTIF(search_ISBI!J2:J686,"N.A")/COUNTA(search_ISBI!J2:J686) -> 0.037037037 | G74: =COUNTIF(search_ISBI!K2:K686,"N.A")/COUNTA(search_ISBI!K2:K686) -> 0 | H74: =COUNTIF(search_ISBI!L2:L686,"N.A")/COUNTA(search_ISBI!L2:L686) -> 0 | I74: =COUNTIF(search_ISBI!M2:M686,"N.A")/COUNTA(search_ISBI!M2:M686) -> 0 | J74: =COUNTIF(search_ISBI!N2:N686,"N.A")/COUNTA(search_ISBI!N2:N686) -> 0 | ... P74: =COUNTIF(search_ISBI!T2:T686,"N.A")/COUNTA(search_ISBI!T2:T686) -> 0
